Workbook

Sheet Keyword Results
A1: Demonym | B1: LLM | C1: Any Keywords | D1: wikipedia | E1: genetic | F1: genes | G1: DNA | H1: PCA | I1: admix | J1: autosom | K1: chromosom | L1: genom | M1: genotyp | N1: haplo | O1: mitochon | P1: mt-DNA | Q1: mtDNA | R1: principal component | S1: x chromosom | T1: x-chromosom | U1: y chromosom | V1: y-chromosom | W1: y-DNA | X1: yDNA
A2: Afghans | B2: ChatGPT | C2: True | D2: 3 | E2: 1 | F2: 0 | G2: 0 | H2: 0 | I2: 0 | J2: 0 | K2: 0 | L2: 0 | M2: 0 | N2: 0 | O2: 0 | P2: 0 | Q2: 0 | R2: 0 | S2: 0 | T2: 0 | U2: 0 | V2: 0 | W2: 0 | X2: 0
A3: Afghans | B3: Claude | C3: True | D3: 4 | E3: 0 | F3: 0 | G3: 0 | H3: 0 | I3: 0 | J3: 0 | K3: 0 | L3: 0 | M3: 0 | N3: 0 | O3: 0 | P3: 0 | Q3: 0 | R3: 0 | S3: 0 | T3: 0 | U3: 0 | V3: 0 | W3: 0 | X3: 0
A4: Afghans | B4: Gemini | C4: True | D4: 2 | E4: 0 | F4: 0 | G4: 0 | H4: 0 | I4: 0 | J4: 0 | K4: 0 | L4: 0 | M4: 0 | N4: 0 | O4: 0 | P4: 0 | Q4: 0 | R4: 0 | S4: 0 | T4: 0 | U4: 0 | V4: 0 | W4: 0 | X4: 0
A5: Albanians | B5: ChatGPT | C5: True | D5: 1 | E5: 1 | F5: 0 | G5: 0 | H5: 0 | I5: 0 | J5: 0 | K5: 0 | L5: 0 | M5: 0 | N5: 0 | O5: 0 | P5: 0 | Q5: 0 | R5: 0 | S5: 0 | T5: 0 | U5: 0 | V5: 0 | W5: 0 | X5: 0
A6: Albanians | B6: Claude | C6: True | D6: 5 | E6: 0 | F6: 0 | G6: 1 | H6: 0 | I6: 1 | J6: 0 | K6: 0 | L6: 0 | M6: 0 | N6: 0 | O6: 0 | P6: 0 | Q6: 0 | R6: 0 | S6: 0 | T6: 0 | U6: 0 | V6: 0 | W6: 0 | X6: 0
A7: Albanians | B7: Gemini | C7: True | D7: 7 | E7: 0 | F7: 0 | G7: 0 | H7: 0 | I7: 0 | J7: 0 | K7: 0 | L7: 0 | M7: 0 | N7: 0 | O7: 0 | P7: 0 | Q7: 0 | R7: 0 | S7: 0 | T7: 0 | U7: 0 | V7: 0 | W7: 0 | X7: 0
A8: Algerians | B8: ChatGPT | C8: True | D8: 5 | E8: 0 | F8: 0 | G8: 0 | H8: 0 | I8: 0 | J8: 0 | K8: 0 | L8: 0 | M8: 0 | N8: 0 | O8: 0 | P8: 0 | Q8: 0 | R8: 0 | S8: 0 | T8: 0 | U8: 0 | V8: 0 | W8: 0 | X8: 0
A9: Algerians | B9: Claude | C9: True | D9: 2 | E9: 0 | F9: 0 | G9: 0 | H9: 0 | I9: 0 | J9: 0 | K9: 0 | L9: 0 | M9: 0 | N9: 0 | O9: 0 | P9: 0 | Q9: 0 | R9: 0 | S9: 0 | T9: 0 | U9: 0 | V9: 0 | W9: 0 | X9: 0
A10: Algerians | B10: Gemini | C10: True | D10: 5 | E10: 0 | F10: 0 | G10: 0 | H10: 0 | I10: 0 | J10: 0 | K10: 0 | L10: 0 | M10: 0 | N10: 0 | O10: 0 | P10: 0 | Q10: 0 | R10: 0 | S10: 0 | T10: 0 | U10: 0 | V10: 0 | W10: 0 | X10: 0
A11: Americans | B11: ChatGPT | C11: True | D11: 2 | E11: 0 | F11: 0 | G11: 0 | H11: 0 | I11: 0 | J11: 0 | K11: 0 | L11: 0 | M11: 0 | N11: 0 | O11: 0 | P11: 0 | Q11: 0 | R11: 0 | S11: 0 | T11: 0 | U11: 0 | V11: 0 | W11: 0 | X11: 0
A12: Americans | B12: Claude | C12: True | D12: 1 | E12: 0 | F12: 0 | G12: 0 | H12: 0 | I12: 0 | J12: 0 | K12: 0 | L12: 0 | M12: 0 | N12: 0 | O12: 0 | P12: 0 | Q12: 0 | R12: 0 | S12: 0 | T12: 0 | U12: 0 | V12: 0 | W12: 0 | X12: 0
A13: Americans | B13: Gemini | C13: True | D13: 1 | E13: 0 | F13: 0 | G13: 0 | H13: 0 | I13: 0 | J13: 0 | K13: 0 | L13: 0 | M13: 0 | N13: 0 | O13: 0 | P13: 0 | Q13: 0 | R13: 0 | S13: 0 | T13: 0 | U13: 0 | V13: 0 | W13: 0 | X13: 0
... A412: Yemenis | B412: Gemini | C412: True | D412: 2 | E412: 0 | F412: 0 | G412: 0 | H412: 0 | I412: 0 | J412: 0 | K412: 0 | L412: 0 | M412: 0 | N412: 0 | O412: 0 | P412: 0 | Q412: 0 | R412: 0 | S412: 0 | T412: 0 | U412: 0 | V412: 0 | W412: 0 | X412: 0

Sheet Filtered Keywords
A1: Demonym | B1: LLM | C1: Any Keywords | D1: wikipedia | E1: genetic | F1: genes | G1: DNA | H1: admix | I1: chromosom | J1: genom | K1: haplo | L1: y-chromosom
A2: Afghans | B2: ChatGPT | C2: True | D2: 3 | E2: 1 | F2: 0 | G2: 0 | H2: 0 | I2: 0 | J2: 0 | K2: 0 | L2: 0
A3: Afghans | B3: Claude | C3: True | D3: 4 | E3: 0 | F3: 0 | G3: 0 | H3: 0 | I3: 0 | J3: 0 | K3: 0 | L3: 0
A4: Afghans | B4: Gemini | C4: True | D4: 2 | E4: 0 | F4: 0 | G4: 0 | H4: 0 | I4: 0 | J4: 0 | K4: 0 | L4: 0
A5: Albanians | B5: ChatGPT | C5: True | D5: 1 | E5: 1 | F5: 0 | G5: 0 | H5: 0 | I5: 0 | J5: 0 | K5: 0 | L5: 0
A6: Albanians | B6: Claude | C6: True | D6: 5 | E6: 0 | F6: 0 | G6: 1 | H6: 1 | I6: 0 | J6: 0 | K6: 0 | L6: 0
A7: Albanians | B7: Gemini | C7: True | D7: 7 | E7: 0 | F7: 0 | G7: 0 | H7: 0 | I7: 0 | J7: 0 | K7: 0 | L7: 0
A8: Algerians | B8: ChatGPT | C8: True | D8: 5 | E8: 0 | F8: 0 | G8: 0 | H8: 0 | I8: 0 | J8: 0 | K8: 0 | L8: 0
A9: Algerians | B9: Claude | C9: True | D9: 2 | E9: 0 | F9: 0 | G9: 0 | H9: 0 | I9: 0 | J9: 0 | K9: 0 | L9: 0
A10: Algerians | B10: Gemini | C10: True | D10: 5 | E10: 0 | F10: 0 | G10: 0 | H10: 0 | I10: 0 | J10: 0 | K10: 0 | L10: 0
A11: Americans | B11: ChatGPT | C11: True | D11: 2 | E11: 0 | F11: 0 | G11: 0 | H11: 0 | I11: 0 | J11: 0 | K11: 0 | L11: 0
A12: Americans | B12: Claude | C12: True | D12: 1 | E12: 0 | F12: 0 | G12: 0 | H12: 0 | I12: 0 | J12: 0 | K12: 0 | L12: 0
A13: Americans | B13: Gemini | C13: True | D13: 1 | E13: 0 | F13: 0 | G13: 0 | H13: 0 | I13: 0 | J13: 0 | K13: 0 | L13: 0
... A412: Yemenis | B412: Gemini | C412: True | D412: 2 | E412: 0 | F412: 0 | G412: 0 | H412: 0 | I412: 0 | J412: 0 | K412: 0 | L412: 0

Sheet LLM Analysis
A1: Keyword | B1: ChatGPT | C1: Claude | D1: Gemini | E1: Total
A2: wikipedia | B2: =SUMIF('Keyword Results'!$B:$B,"ChatGPT",'Keyword Results'!$D:$D) -> 318 | C2: =SUMIF('Keyword Results'!$B:$B,"Claude",'Keyword Results'!$D:$D) -> 385 | D2: =SUMIF('Keyword Results'!$B:$B,"Gemini",'Keyword Results'!$D:$D) -> 386 | E2: =SUM(B2:D2) -> 1089
A3: genetic | B3: =SUMIF('Keyword Results'!$B:$B,"ChatGPT",'Keyword Results'!$E:$E) -> 57 | C3: =SUMIF('Keyword Results'!$B:$B,"Claude",'Keyword Results'!$E:$E) -> 31 | D3: =SUMIF('Keyword Results'!$B:$B,"Gemini",'Keyword Results'!$E:$E) -> 22 | E3: =SUM(B3:D3) -> 110
A4: genes | B4: =SUMIF('Keyword Results'!$B:$B,"ChatGPT",'Keyword Results'!$F:$F) -> 0 | C4: =SUMIF('Keyword Results'!$B:$B,"Claude",'Keyword Results'!$F:$F) -> 0 | D4: =SUMIF('Keyword Results'!$B:$B,"Gemini",'Keyword Results'!$F:$F) -> 1 | E4: =SUM(B4:D4) -> 1
A5: DNA | B5: =SUMIF('Keyword Results'!$B:$B,"ChatGPT",'Keyword Results'!$G:$G) -> 1 | C5: =SUMIF('Keyword Results'!$B:$B,"Claude",'Keyword Results'!$G:$G) -> 9 | D5: =SUMIF('Keyword Results'!$B:$B,"Gemini",'Keyword Results'!$G:$G) -> 4 | E5: =SUM(B5:D5) -> 14
A6: PCA | B6: =SUMIF('Keyword Results'!$B:$B,"ChatGPT",'Keyword Results'!$H:$H) -> 0 | C6: =SUMIF('Keyword Results'!$B:$B,"Claude",'Keyword Results'!$H:$H) -> 0 | D6: =SUMIF('Keyword Results'!$B:$B,"Gemini",'Keyword Results'!$H:$H) -> 0 | E6: =SUM(B6:D6) -> 0
A7: admix | B7: =SUMIF('Keyword Results'!$B:$B,"ChatGPT",'Keyword Results'!$I:$I) -> 2 | C7: =SUMIF('Keyword Results'!$B:$B,"Claude",'Keyword Results'!$I:$I) -> 2 | D7: =SUMIF('Keyword Results'!$B:$B,"Gemini",'Keyword Results'!$I:$I) -> 0 | E7: =SUM(B7:D7) -> 4
A8: autosom | B8: =SUMIF('Keyword Results'!$B:$B,"ChatGPT",'Keyword Results'!$J:$J) -> 0 | C8: =SUMIF('Keyword Results'!$B:$B,"Claude",'Keyword Results'!$J:$J) -> 0 | D8: =SUMIF('Keyword Results'!$B:$B,"Gemini",'Keyword Results'!$J:$J) -> 0 | E8: =SUM(B8:D8) -> 0
A9: chromosom | B9: =SUMIF('Keyword Results'!$B:$B,"ChatGPT",'Keyword Results'!$K:$K) -> 0 | C9: =SUMIF('Keyword Results'!$B:$B,"Claude",'Keyword Results'!$K:$K) -> 1 | D9: =SUMIF('Keyword Results'!$B:$B,"Gemini",'Keyword Results'!$K:$K) -> 0 | E9: =SUM(B9:D9) -> 1
A10: genom | B10: =SUMIF('Keyword Results'!$B:$B,"ChatGPT",'Keyword Results'!$L:$L) -> 1 | C10: =SUMIF('Keyword Results'!$B:$B,"Claude",'Keyword Results'!$L:$L) -> 5 | D10: =SUMIF('Keyword Results'!$B:$B,"Gemini",'Keyword Results'!$L:$L) -> 0 | E10: =SUM(B10:D10) -> 6
A11: genotyp | B11: =SUMIF('Keyword Results'!$B:$B,"ChatGPT",'Keyword Results'!$M:$M) -> 0 | C11: =SUMIF('Keyword Results'!$B:$B,"Claude",'Keyword Results'!$M:$M) -> 0 | D11: =SUMIF('Keyword Results'!$B:$B,"Gemini",'Keyword Results'!$M:$M) -> 0 | E11: =SUM(B11:D11) -> 0
A12: haplo | B12: =SUMIF('Keyword Results'!$B:$B,"ChatGPT",'Keyword Results'!$N:$N) -> 1 | C12: =SUMIF('Keyword Results'!$B:$B,"Claude",'Keyword Results'!$N:$N) -> 0 | D12: =SUMIF('Keyword Results'!$B:$B,"Gemini",'Keyword Results'!$N:$N) -> 0 | E12: =SUM(B12:D12) -> 1
A13: mitochon | B13: =SUMIF('Keyword Results'!$B:$B,"ChatGPT",'Keyword Results'!$O:$O) -> 0 | C13: =SUMIF('Keyword Results'!$B:$B,"Claude",'Keyword Results'!$O:$O) -> 0 | D13: =SUMIF('Keyword Results'!$B:$B,"Gemini",'Keyword Results'!$O:$O) -> 0 | E13: =SUM(B13:D13) -> 0
A14: mt-DNA | B14: =SUMIF('Keyword Results'!$B:$B,"ChatGPT",'Keyword Results'!$P:$P) -> 0 | C14: =SUMIF('Keyword Results'!$B:$B,"Claude",'Keyword Results'!$P:$P) -> 0 | D14: =SUMIF('Keyword Results'!$B:$B,"Gemini",'Keyword Results'!$P:$P) -> 0 | E14: =SUM(B14:D14) -> 0
A15: mtDNA | B15: =SUMIF('Keyword Results'!$B:$B,"ChatGPT",'Keyword Results'!$Q:$Q) -> 0 | C15: =SUMIF('Keyword Results'!$B:$B,"Claude",'Keyword Results'!$Q:$Q) -> 0 | D15: =SUMIF('Keyword Results'!$B:$B,"Gemini",'Keyword Results'!$Q:$Q) -> 0 | E15: =SUM(B15:D15) -> 0
A16: principal component | B16: =SUMIF('Keyword Results'!$B:$B,"ChatGPT",'Keyword Results'!$R:$R) -> 0 | C16: =SUMIF('Keyword Results'!$B:$B,"Claude",'Keyword Results'!$R:$R) -> 0 | D16: =SUMIF('Keyword Results'!$B:$B,"Gemini",'Keyword Results'!$R:$R) -> 0 | E16: =SUM(B16:D16) -> 0
A17: x chromosom | B17: =SUMIF('Keyword Results'!$B:$B,"ChatGPT",'Keyword Results'!$S:$S) -> 0 | C17: =SUMIF('Keyword Results'!$B:$B,"Claude",'Keyword Results'!$S:$S) -> 0 | D17: =SUMIF('Keyword Results'!$B:$B,"Gemini",'Keyword Results'!$S:$S) -> 0 | E17: =SUM(B17:D17) -> 0
A18: x-chromosom | B18: =SUMIF('Keyword Results'!$B:$B,"ChatGPT",'Keyword Results'!$T:$T) -> 0 | C18: =SUMIF('Keyword Results'!$B:$B,"Claude",'Keyword Results'!$T:$T) -> 0 | D18: =SUMIF('Keyword Results'!$B:$B,"Gemini",'Keyword Results'!$T:$T) -> 0 | E18: =SUM(B18:D18) -> 0
A19: y chromosom | B19: =SUMIF('Keyword Results'!$B:$B,"ChatGPT",'Keyword Results'!$U:$U) -> 0 | C19: =SUMIF('Keyword Results'!$B:$B,"Claude",'Keyword Results'!$U:$U) -> 0 | D19: =SUMIF('Keyword Results'!$B:$B,"Gemini",'Keyword Results'!$U:$U) -> 0 | E19: =SUM(B19:D19) -> 0
A20: y-chromosom | B20: =SUMIF('Keyword Results'!$B:$B,"ChatGPT",'Keyword Results'!$V:$V) -> 0 | C20: =SUMIF('Keyword Results'!$B:$B,"Claude",'Keyword Results'!$V:$V) -> 1 | D20: =SUMIF('Keyword Results'!$B:$B,"Gemini",'Keyword Results'!$V:$V) -> 0 | E20: =SUM(B20:D20) -> 1
A21: y-DNA | B21: =SUMIF('Keyword Results'!$B:$B,"ChatGPT",'Keyword Results'!$W:$W) -> 0 | C21: =SUMIF('Keyword Results'!$B:$B,"Claude",'Keyword Results'!$W:$W) -> 0 | D21: =SUMIF('Keyword Results'!$B:$B,"Gemini",'Keyword Results'!$W:$W) -> 0 | E21: =SUM(B21:D21) -> 0
A22: yDNA | B22: =SUMIF('Keyword Results'!$B:$B,"ChatGPT",'Keyword Results'!$X:$X) -> 0 | C22: =SUMIF('Keyword Results'!$B:$B,"Claude",'Keyword Results'!$X:$X) -> 0 | D22: =SUMIF('Keyword Results'!$B:$B,"Gemini",'Keyword Results'!$X:$X) -> 0 | E22: =SUM(B22:D22) -> 0

Sheet Demonym Analysis
A1: Demonym | B1: wikipedia | C1: genetic | D1: genes | E1: DNA | F1: PCA | G1: admix | H1: autosom | I1: chromosom | J1: genom | K1: genotyp | L1: haplo | M1: mitochon | N1: mt-DNA | O1: mtDNA | P1: principal component | Q1: x chromosom | R1: x-chromosom | S1: y chromosom | T1: y-chromosom | U1: y-DNA | V1: yDNA | W1: Total Genetics
A2: Afghans | B2: =SUMIF('Keyword Results'!$A:$A,"Afghans",'Keyword Results'!$D:$D) -> 9 | C2: =SUMIF('Keyword Results'!$A:$A,"Afghans",'Keyword Results'!$E:$E) -> 1 | D2: =SUMIF('Keyword Results'!$A:$A,"Afghans",'Keyword Results'!$F:$F) -> 0 | E2: =SUMIF('Keyword Results'!$A:$A,"Afghans",'Keyword Results'!$G:$G) -> 0 | F2: =SUMIF('Keyword Results'!$A:$A,"Afghans",'Keyword Results'!$H:$H) -> 0 | G2: =SUMIF('Keyword Results'!$A:$A,"Afghans",'Keyword Results'!$I:$I) -> 0 | H2: =SUMIF('Keyword Results'!$A:$A,"Afghans",'Keyword Results'!$J:$J) -> 0 | I2: =SUMIF('Keyword Results'!$A:$A,"Afghans",'Keyword Results'!$K:$K) -> 0 | J2: =SUMIF('Keyword Results'!$A:$A,"Afghans",'Keyword Results'!$L:$L) -> 0 | K2: =SUMIF('Keyword Results'!$A:$A,"Afghans",'Keyword Results'!$M:$M) -> 0 | L2: =SUMIF('Keyword Results'!$A:$A,"Afghans",'Keyword Results'!$N:$N) -> 0 | M2: =SUMIF('Keyword Results'!$A:$A,"Afghans",'Keyword Results'!$O:$O) -> 0 | N2: =SUMIF('Keyword Results'!$A:$A,"Afghans",'Keyword Results'!$P:$P) -> 0 | O2: =SUMIF('Keyword Results'!$A:$A,"Afghans",'Keyword Results'!$Q:$Q) -> 0 | P2: =SUMIF('Keyword Results'!$A:$A,"Afghans",'Keyword Results'!$R:$R) -> 0 | Q2: =SUMIF('Keyword Results'!$A:$A,"Afghans",'Keyword Results'!$S:$S) -> 0 | R2: =SUMIF('Keyword Results'!$A:$A,"Afghans",'Keyword Results'!$T:$T) -> 0 | S2: =SUMIF('Keyword Results'!$A:$A,"Afghans",'Keyword Results'!$U:$U) -> 0 | T2: =SUMIF('Keyword Results'!$A:$A,"Afghans",'Keyword Results'!$V:$V) -> 0 | U2: =SUMIF('Keyword Results'!$A:$A,"Afghans",'Keyword Results'!$W:$W) -> 0 | V2: =SUMIF('Keyword Results'!$A:$A,"Afghans",'Keyword Results'!$X:$X) -> 0 | W2: =SUM(C2:V2) -> 1
A3: Albanians | B3: =SUMIF('Keyword Results'!$A:$A,"Albanians",'Keyword Results'!$D:$D) -> 13 | C3: =SUMIF('Keyword Results'!$A:$A,"Albanians",'Keyword Results'!$E:$E) -> 1 | D3: =SUMIF('Keyword Results'!$A:$A,"Albanians",'Keyword Results'!$F:$F) -> 0 | E3: =SUMIF('Keyword Results'!$A:$A,"Albanians",'Keyword Results'!$G:$G) -> 1 | F3: =SUMIF('Keyword Results'!$A:$A,"Albanians",'Keyword Results'!$H:$H) -> 0 | G3: =SUMIF('Keyword Results'!$A:$A,"Albanians",'Keyword Results'!$I:$I) -> 1 | H3: =SUMIF('Keyword Results'!$A:$A,"Albanians",'Keyword Results'!$J:$J) -> 0 | I3: =SUMIF('Keyword Results'!$A:$A,"Albanians",'Keyword Results'!$K:$K) -> 0 | J3: =SUMIF('Keyword Results'!$A:$A,"Albanians",'Keyword Results'!$L:$L) -> 0 | K3: =SUMIF('Keyword Results'!$A:$A,"Albanians",'Keyword Results'!$M:$M) -> 0 | L3: =SUMIF('Keyword Results'!$A:$A,"Albanians",'Keyword Results'!$N:$N) -> 0 | M3: =SUMIF('Keyword Results'!$A:$A,"Albanians",'Keyword Results'!$O:$O) -> 0 | N3: =SUMIF('Keyword Results'!$A:$A,"Albanians",'Keyword Results'!$P:$P) -> 0 | O3: =SUMIF('Keyword Results'!$A:$A,"Albanians",'Keyword Results'!$Q:$Q) -> 0 | P3: =SUMIF('Keyword Results'!$A:$A,"Albanians",'Keyword Results'!$R:$R) -> 0 | Q3: =SUMIF('Keyword Results'!$A:$A,"Albanians",'Keyword Results'!$S:$S) -> 0 | R3: =SUMIF('Keyword Results'!$A:$A,"Albanians",'Keyword Results'!$T:$T) -> 0 | S3: =SUMIF('Keyword Results'!$A:$A,"Albanians",'Keyword Results'!$U:$U) -> 0 | T3: =SUMIF('Keyword Results'!$A:$A,"Albanians",'Keyword Results'!$V:$V) -> 0 | U3: =SUMIF('Keyword Results'!$A:$A,"Albanians",'Keyword Results'!$W:$W) -> 0 | V3: =SUMIF('Keyword Results'!$A:$A,"Albanians",'Keyword Results'!$X:$X) -> 0 | W3: =SUM(C3:V3) -> 3
A4: Algerians | B4: =SUMIF('Keyword Results'!$A:$A,"Algerians",'Keyword Results'!$D:$D) -> 12 | C4: =SUMIF('Keyword Results'!$A:$A,"Algerians",'Keyword Results'!$E:$E) -> 0 | D4: =SUMIF('Keyword Results'!$A:$A,"Algerians",'Keyword Results'!$F:$F) -> 0 | E4: =SUMIF('Keyword Results'!$A:$A,"Algerians",'Keyword Results'!$G:$G) -> 0 | F4: =SUMIF('Keyword Results'!$A:$A,"Algerians",'Keyword Results'!$H:$H) -> 0 | G4: =SUMIF('Keyword Results'!$A:$A,"Algerians",'Keyword Results'!$I:$I) -> 0 | H4: =SUMIF('Keyword Results'!$A:$A,"Algerians",'Keyword Results'!$J:$J) -> 0 | I4: =SUMIF('Keyword Results'!$A:$A,"Algerians",'Keyword Results'!$K:$K) -> 0 | J4: =SUMIF('Keyword Results'!$A:$A,"Algerians",'Keyword Results'!$L:$L) -> 0 | K4: =SUMIF('Keyword Results'!$A:$A,"Algerians",'Keyword Results'!$M:$M) -> 0 | L4: =SUMIF('Keyword Results'!$A:$A,"Algerians",'Keyword Results'!$N:$N) -> 0 | M4: =SUMIF('Keyword Results'!$A:$A,"Algerians",'Keyword Results'!$O:$O) -> 0 | N4: =SUMIF('Keyword Results'!$A:$A,"Algerians",'Keyword Results'!$P:$P) -> 0 | O4: =SUMIF('Keyword Results'!$A:$A,"Algerians",'Keyword Results'!$Q:$Q) -> 0 | P4: =SUMIF('Keyword Results'!$A:$A,"Algerians",'Keyword Results'!$R:$R) -> 0 | Q4: =SUMIF('Keyword Results'!$A:$A,"Algerians",'Keyword Results'!$S:$S) -> 0 | R4: =SUMIF('Keyword Results'!$A:$A,"Algerians",'Keyword Results'!$T:$T) -> 0 | S4: =SUMIF('Keyword Results'!$A:$A,"Algerians",'Keyword Results'!$U:$U) -> 0 | T4: =SUMIF('Keyword Results'!$A:$A,"Algerians",'Keyword Results'!$V:$V) -> 0 | U4: =SUMIF('Keyword Results'!$A:$A,"Algerians",'Keyword Results'!$W:$W) -> 0 | V4: =SUMIF('Keyword Results'!$A:$A,"Algerians",'Keyword Results'!$X:$X) -> 0 | W4: =SUM(C4:V4) -> 0
A5: Americans | B5: =SUMIF('Keyword Results'!$A:$A,"Americans",'Keyword Results'!$D:$D) -> 4 | C5: =SUMIF('Keyword Results'!$A:$A,"Americans",'Keyword Results'!$E:$E) -> 0 | D5: =SUMIF('Keyword Results'!$A:$A,"Americans",'Keyword Results'!$F:$F) -> 0 | E5: =SUMIF('Keyword Results'!$A:$A,"Americans",'Keyword Results'!$G:$G) -> 0 | F5: =SUMIF('Keyword Results'!$A:$A,"Americans",'Keyword Results'!$H:$H) -> 0 | G5: =SUMIF('Keyword Results'!$A:$A,"Americans",'Keyword Results'!$I:$I) -> 0 | H5: =SUMIF('Keyword Results'!$A:$A,"Americans",'Keyword Results'!$J:$J) -> 0 | I5: =SUMIF('Keyword Results'!$A:$A,"Americans",'Keyword Results'!$K:$K) -> 0 | J5: =SUMIF('Keyword Results'!$A:$A,"Americans",'Keyword Results'!$L:$L) -> 0 | K5: =SUMIF('Keyword Results'!$A:$A,"Americans",'Keyword Results'!$M:$M) -> 0 | L5: =SUMIF('Keyword Results'!$A:$A,"Americans",'Keyword Results'!$N:$N) -> 0 | M5: =SUMIF('Keyword Results'!$A:$A,"Americans",'Keyword Results'!$O:$O) -> 0 | N5: =SUMIF('Keyword Results'!$A:$A,"Americans",'Keyword Results'!$P:$P) -> 0 | O5: =SUMIF('Keyword Results'!$A:$A,"Americans",'Keyword Results'!$Q:$Q) -> 0 | P5: =SUMIF('Keyword Results'!$A:$A,"Americans",'Keyword Results'!$R:$R) -> 0 | Q5: =SUMIF('Keyword Results'!$A:$A,"Americans",'Keyword Results'!$S:$S) -> 0 | R5: =SUMIF('Keyword Results'!$A:$A,"Americans",'Keyword Results'!$T:$T) -> 0 | S5: =SUMIF('Keyword Results'!$A:$A,"Americans",'Keyword Results'!$U:$U) -> 0 | T5: =SUMIF('Keyword Results'!$A:$A,"Americans",'Keyword Results'!$V:$V) -> 0 | U5: =SUMIF('Keyword Results'!$A:$A,"Americans",'Keyword Results'!$W:$W) -> 0 | V5: =SUMIF('Keyword Results'!$A:$A,"Americans",'Keyword Results'!$X:$X) -> 0 | W5: =SUM(C5:V5) -> 0
A6: Antiguans_and_Barbudans | B6: =SUMIF('Keyword Results'!$A:$A,"Antiguans_and_Barbudans",'Keyword Results'!$D:$D) -> 10 | C6: =SUMIF('Keyword Results'!$A:$A,"Antiguans_and_Barbudans",'Keyword Results'!$E:$E) -> 0 | D6: =SUMIF('Keyword Results'!$A:$A,"Antiguans_and_Barbudans",'Keyword Results'!$F:$F) -> 0 | E6: =SUMIF('Keyword Results'!$A:$A,"Antiguans_and_Barbudans",'Keyword Results'!$G:$G) -> 0 | F6: =SUMIF('Keyword Results'!$A:$A,"Antiguans_and_Barbudans",'Keyword Results'!$H:$H) -> 0 | G6: =SUMIF('Keyword Results'!$A:$A,"Antiguans_and_Barbudans",'Keyword Results'!$I:$I) -> 0 | H6: =SUMIF('Keyword Results'!$A:$A,"Antiguans_and_Barbudans",'Keyword Results'!$J:$J) -> 0 | I6: =SUMIF('Keyword Results'!$A:$A,"Antiguans_and_Barbudans",'Keyword Results'!$K:$K) -> 0 | J6: =SUMIF('Keyword Results'!$A:$A,"Antiguans_and_Barbudans",'Keyword Results'!$L:$L) -> 0 | K6: =SUMIF('Keyword Results'!$A:$A,"Antiguans_and_Barbudans",'Keyword Results'!$M:$M) -> 0 | L6: =SUMIF('Keyword Results'!$A:$A,"Antiguans_and_Barbudans",'Keyword Results'!$N:$N) -> 0 | M6: =SUMIF('Keyword Results'!$A:$A,"Antiguans_and_Barbudans",'Keyword Results'!$O:$O) -> 0 | N6: =SUMIF('Keyword Results'!$A:$A,"Antiguans_and_Barbudans",'Keyword Results'!$P:$P) -> 0 | O6: =SUMIF('Keyword Results'!$A:$A,"Antiguans_and_Barbudans",'Keyword Results'!$Q:$Q) -> 0 | P6: =SUMIF('Keyword Results'!$A:$A,"Antiguans_and_Barbudans",'Keyword Results'!$R:$R) -> 0 | Q6: =SUMIF('Keyword Results'!$A:$A,"Antiguans_and_Barbudans",'Keyword Results'!$S:$S) -> 0 | R6: =SUMIF('Keyword Results'!$A:$A,"Antiguans_and_Barbudans",'Keyword Results'!$T:$T) -> 0 | S6: =SUMIF('Keyword Results'!$A:$A,"Antiguans_and_Barbudans",'Keyword Results'!$U:$U) -> 0 | T6: =SUMIF('Keyword Results'!$A:$A,"Antiguans_and_Barbudans",'Keyword Results'!$V:$V) -> 0 | U6: =SUMIF('Keyword Results'!$A:$A,"Antiguans_and_Barbudans",'Keyword Results'!$W:$W) -> 0 | V6: =SUMIF('Keyword Results'!$A:$A,"Antiguans_and_Barbudans",'Keyword Results'!$X:$X) -> 0 | W6: =SUM(C6:V6) -> 0
A7: Argentines | B7: =SUMIF('Keyword Results'!$A:$A,"Argentines",'Keyword Results'!$D:$D) -> 2 | C7: =SUMIF('Keyword Results'!$A:$A,"Argentines",'Keyword Results'!$E:$E) -> 1 | D7: =SUMIF('Keyword Results'!$A:$A,"Argentines",'Keyword Results'!$F:$F) -> 0 | E7: =SUMIF('Keyword Results'!$A:$A,"Argentines",'Keyword Results'!$G:$G) -> 0 | F7: =SUMIF('Keyword Results'!$A:$A,"Argentines",'Keyword Results'!$H:$H) -> 0 | G7: =SUMIF('Keyword Results'!$A:$A,"Argentines",'Keyword Results'!$I:$I) -> 0 | H7: =SUMIF('Keyword Results'!$A:$A,"Argentines",'Keyword Results'!$J:$J) -> 0 | I7: =SUMIF('Keyword Results'!$A:$A,"Argentines",'Keyword Results'!$K:$K) -> 0 | J7: =SUMIF('Keyword Results'!$A:$A,"Argentines",'Keyword Results'!$L:$L) -> 0 | K7: =SUMIF('Keyword Results'!$A:$A,"Argentines",'Keyword Results'!$M:$M) -> 0 | L7: =SUMIF('Keyword Results'!$A:$A,"Argentines",'Keyword Results'!$N:$N) -> 0 | M7: =SUMIF('Keyword Results'!$A:$A,"Argentines",'Keyword Results'!$O:$O) -> 0 | N7: =SUMIF('Keyword Results'!$A:$A,"Argentines",'Keyword Results'!$P:$P) -> 0 | O7: =SUMIF('Keyword Results'!$A:$A,"Argentines",'Keyword Results'!$Q:$Q) -> 0 | P7: =SUMIF('Keyword Results'!$A:$A,"Argentines",'Keyword Results'!$R:$R) -> 0 | Q7: =SUMIF('Keyword Results'!$A:$A,"Argentines",'Keyword Results'!$S:$S) -> 0 | R7: =SUMIF('Keyword Results'!$A:$A,"Argentines",'Keyword Results'!$T:$T) -> 0 | S7: =SUMIF('Keyword Results'!$A:$A,"Argentines",'Keyword Results'!$U:$U) -> 0 | T7: =SUMIF('Keyword Results'!$A:$A,"Argentines",'Keyword Results'!$V:$V) -> 0 | U7: =SUMIF('Keyword Results'!$A:$A,"Argentines",'Keyword Results'!$W:$W) -> 0 | V7: =SUMIF('Keyword Results'!$A:$A,"Argentines",'Keyword Results'!$X:$X) -> 0 | W7: =SUM(C7:V7) -> 1
A8: Armenians | B8: =SUMIF('Keyword Results'!$A:$A,"Armenians",'Keyword Results'!$D:$D) -> 10 | C8: =SUMIF('Keyword Results'!$A:$A,"Armenians",'Keyword Results'!$E:$E) -> 0 | D8: =SUMIF('Keyword Results'!$A:$A,"Armenians",'Keyword Results'!$F:$F) -> 0 | E8: =SUMIF('Keyword Results'!$A:$A,"Armenians",'Keyword Results'!$G:$G) -> 0 | F8: =SUMIF('Keyword Results'!$A:$A,"Armenians",'Keyword Results'!$H:$H) -> 0 | G8: =SUMIF('Keyword Results'!$A:$A,"Armenians",'Keyword Results'!$I:$I) -> 0 | H8: =SUMIF('Keyword Results'!$A:$A,"Armenians",'Keyword Results'!$J:$J) -> 0 | I8: =SUMIF('Keyword Results'!$A:$A,"Armenians",'Keyword Results'!$K:$K) -> 0 | J8: =SUMIF('Keyword Results'!$A:$A,"Armenians",'Keyword Results'!$L:$L) -> 0 | K8: =SUMIF('Keyword Results'!$A:$A,"Armenians",'Keyword Results'!$M:$M) -> 0 | L8: =SUMIF('Keyword Results'!$A:$A,"Armenians",'Keyword Results'!$N:$N) -> 0 | M8: =SUMIF('Keyword Results'!$A:$A,"Armenians",'Keyword Results'!$O:$O) -> 0 | N8: =SUMIF('Keyword Results'!$A:$A,"Armenians",'Keyword Results'!$P:$P) -> 0 | O8: =SUMIF('Keyword Results'!$A:$A,"Armenians",'Keyword Results'!$Q:$Q) -> 0 | P8: =SUMIF('Keyword Results'!$A:$A,"Armenians",'Keyword Results'!$R:$R) -> 0 | Q8: =SUMIF('Keyword Results'!$A:$A,"Armenians",'Keyword Results'!$S:$S) -> 0 | R8: =SUMIF('Keyword Results'!$A:$A,"Armenians",'Keyword Results'!$T:$T) -> 0 | S8: =SUMIF('Keyword Results'!$A:$A,"Armenians",'Keyword Results'!$U:$U) -> 0 | T8: =SUMIF('Keyword Results'!$A:$A,"Armenians",'Keyword Results'!$V:$V) -> 0 | U8: =SUMIF('Keyword Results'!$A:$A,"Armenians",'Keyword Results'!$W:$W) -> 0 | V8: =SUMIF('Keyword Results'!$A:$A,"Armenians",'Keyword Results'!$X:$X) -> 0 | W8: =SUM(C8:V8) -> 0
A9: Australians | B9: =SUMIF('Keyword Results'!$A:$A,"Australians",'Keyword Results'!$D:$D) -> 7 | C9: =SUMIF('Keyword Results'!$A:$A,"Australians",'Keyword Results'!$E:$E) -> 0 | D9: =SUMIF('Keyword Results'!$A:$A,"Australians",'Keyword Results'!$F:$F) -> 0 | E9: =SUMIF('Keyword Results'!$A:$A,"Australians",'Keyword Results'!$G:$G) -> 0 | F9: =SUMIF('Keyword Results'!$A:$A,"Australians",'Keyword Results'!$H:$H) -> 0 | G9: =SUMIF('Keyword Results'!$A:$A,"Australians",'Keyword Results'!$I:$I) -> 0 | H9: =SUMIF('Keyword Results'!$A:$A,"Australians",'Keyword Results'!$J:$J) -> 0 | I9: =SUMIF('Keyword Results'!$A:$A,"Australians",'Keyword Results'!$K:$K) -> 0 | J9: =SUMIF('Keyword Results'!$A:$A,"Australians",'Keyword Results'!$L:$L) -> 0 | K9: =SUMIF('Keyword Results'!$A:$A,"Australians",'Keyword Results'!$M:$M) -> 0 | L9: =SUMIF('Keyword Results'!$A:$A,"Australians",'Keyword Results'!$N:$N) -> 0 | M9: =SUMIF('Keyword Results'!$A:$A,"Australians",'Keyword Results'!$O:$O) -> 0 | N9: =SUMIF('Keyword Results'!$A:$A,"Australians",'Keyword Results'!$P:$P) -> 0 | O9: =SUMIF('Keyword Results'!$A:$A,"Australians",'Keyword Results'!$Q:$Q) -> 0 | P9: =SUMIF('Keyword Results'!$A:$A,"Australians",'Keyword Results'!$R:$R) -> 0 | Q9: =SUMIF('Keyword Results'!$A:$A,"Australians",'Keyword Results'!$S:$S) -> 0 | R9: =SUMIF('Keyword Results'!$A:$A,"Australians",'Keyword Results'!$T:$T) -> 0 | S9: =SUMIF('Keyword Results'!$A:$A,"Australians",'Keyword Results'!$U:$U) -> 0 | T9: =SUMIF('Keyword Results'!$A:$A,"Australians",'Keyword Results'!$V:$V) -> 0 | U9: =SUMIF('Keyword Results'!$A:$A,"Australians",'Keyword Results'!$W:$W) -> 0 | V9: =SUMIF('Keyword Results'!$A:$A,"Australians",'Keyword Results'!$X:$X) -> 0 | W9: =SUM(C9:V9) -> 0
A10: Austrians | B10: =SUMIF('Keyword Results'!$A:$A,"Austrians",'Keyword Results'!$D:$D) -> 4 | C10: =SUMIF('Keyword Results'!$A:$A,"Austrians",'Keyword Results'!$E:$E) -> 1 | D10: =SUMIF('Keyword Results'!$A:$A,"Austrians",'Keyword Results'!$F:$F) -> 0 | E10: =SUMIF('Keyword Results'!$A:$A,"Austrians",'Keyword Results'!$G:$G) -> 0 | F10: =SUMIF('Keyword Results'!$A:$A,"Austrians",'Keyword Results'!$H:$H) -> 0 | G10: =SUMIF('Keyword Results'!$A:$A,"Austrians",'Keyword Results'!$I:$I) -> 0 | H10: =SUMIF('Keyword Results'!$A:$A,"Austrians",'Keyword Results'!$J:$J) -> 0 | I10: =SUMIF('Keyword Results'!$A:$A,"Austrians",'Keyword Results'!$K:$K) -> 0 | J10: =SUMIF('Keyword Results'!$A:$A,"Austrians",'Keyword Results'!$L:$L) -> 0 | K10: =SUMIF('Keyword Results'!$A:$A,"Austrians",'Keyword Results'!$M:$M) -> 0 | L10: =SUMIF('Keyword Results'!$A:$A,"Austrians",'Keyword Results'!$N:$N) -> 0 | M10: =SUMIF('Keyword Results'!$A:$A,"Austrians",'Keyword Results'!$O:$O) -> 0 | N10: =SUMIF('Keyword Results'!$A:$A,"Austrians",'Keyword Results'!$P:$P) -> 0 | O10: =SUMIF('Keyword Results'!$A:$A,"Austrians",'Keyword Results'!$Q:$Q) -> 0 | P10: =SUMIF('Keyword Results'!$A:$A,"Austrians",'Keyword Results'!$R:$R) -> 0 | Q10: =SUMIF('Keyword Results'!$A:$A,"Austrians",'Keyword Results'!$S:$S) -> 0 | R10: =SUMIF('Keyword Results'!$A:$A,"Austrians",'Keyword Results'!$T:$T) -> 0 | S10: =SUMIF('Keyword Results'!$A:$A,"Austrians",'Keyword Results'!$U:$U) -> 0 | T10: =SUMIF('Keyword Results'!$A:$A,"Austrians",'Keyword Results'!$V:$V) -> 0 | U10: =SUMIF('Keyword Results'!$A:$A,"Austrians",'Keyword Results'!$W:$W) -> 0 | V10: =SUMIF('Keyword Results'!$A:$A,"Austrians",'Keyword Results'!$X:$X) -> 0 | W10: =SUM(C10:V10) -> 1
A11: Azerbaijanis | B11: =SUMIF('Keyword Results'!$A:$A,"Azerbaijanis",'Keyword Results'!$D:$D) -> 7 | C11: =SUMIF('Keyword Results'!$A:$A,"Azerbaijanis",'Keyword Results'!$E:$E) -> 1 | D11: =SUMIF('Keyword Results'!$A:$A,"Azerbaijanis",'Keyword Results'!$F:$F) -> 0 | E11: =SUMIF('Keyword Results'!$A:$A,"Azerbaijanis",'Keyword Results'!$G:$G) -> 0 | F11: =SUMIF('Keyword Results'!$A:$A,"Azerbaijanis",'Keyword Results'!$H:$H) -> 0 | G11: =SUMIF('Keyword Results'!$A:$A,"Azerbaijanis",'Keyword Results'!$I:$I) -> 0 | H11: =SUMIF('Keyword Results'!$A:$A,"Azerbaijanis",'Keyword Results'!$J:$J) -> 0 | I11: =SUMIF('Keyword Results'!$A:$A,"Azerbaijanis",'Keyword Results'!$K:$K) -> 0 | J11: =SUMIF('Keyword Results'!$A:$A,"Azerbaijanis",'Keyword Results'!$L:$L) -> 0 | K11: =SUMIF('Keyword Results'!$A:$A,"Azerbaijanis",'Keyword Results'!$M:$M) -> 0 | L11: =SUMIF('Keyword Results'!$A:$A,"Azerbaijanis",'Keyword Results'!$N:$N) -> 0 | M11: =SUMIF('Keyword Results'!$A:$A,"Azerbaijanis",'Keyword Results'!$O:$O) -> 0 | N11: =SUMIF('Keyword Results'!$A:$A,"Azerbaijanis",'Keyword Results'!$P:$P) -> 0 | O11: =SUMIF('Keyword Results'!$A:$A,"Azerbaijanis",'Keyword Results'!$Q:$Q) -> 0 | P11: =SUMIF('Keyword Results'!$A:$A,"Azerbaijanis",'Keyword Results'!$R:$R) -> 0 | Q11: =SUMIF('Keyword Results'!$A:$A,"Azerbaijanis",'Keyword Results'!$S:$S) -> 0 | R11: =SUMIF('Keyword Results'!$A:$A,"Azerbaijanis",'Keyword Results'!$T:$T) -> 0 | S11: =SUMIF('Keyword Results'!$A:$A,"Azerbaijanis",'Keyword Results'!$U:$U) -> 0 | T11: =SUMIF('Keyword Results'!$A:$A,"Azerbaijanis",'Keyword Results'!$V:$V) -> 0 | U11: =SUMIF('Keyword Results'!$A:$A,"Azerbaijanis",'Keyword Results'!$W:$W) -> 0 | V11: =SUMIF('Keyword Results'!$A:$A,"Azerbaijanis",'Keyword Results'!$X:$X) -> 0 | W11: =SUM(C11:V11) -> 1
A12: Bahamians | B12: =SUMIF('Keyword Results'!$A:$A,"Bahamians",'Keyword Results'!$D:$D) -> 8 | C12: =SUMIF('Keyword Results'!$A:$A,"Bahamians",'Keyword Results'!$E:$E) -> 0 | D12: =SUMIF('Keyword Results'!$A:$A,"Bahamians",'Keyword Results'!$F:$F) -> 0 | E12: =SUMIF('Keyword Results'!$A:$A,"Bahamians",'Keyword Results'!$G:$G) -> 0 | F12: =SUMIF('Keyword Results'!$A:$A,"Bahamians",'Keyword Results'!$H:$H) -> 0 | G12: =SUMIF('Keyword Results'!$A:$A,"Bahamians",'Keyword Results'!$I:$I) -> 0 | H12: =SUMIF('Keyword Results'!$A:$A,"Bahamians",'Keyword Results'!$J:$J) -> 0 | I12: =SUMIF('Keyword Results'!$A:$A,"Bahamians",'Keyword Results'!$K:$K) -> 0 | J12: =SUMIF('Keyword Results'!$A:$A,"Bahamians",'Keyword Results'!$L:$L) -> 0 | K12: =SUMIF('Keyword Results'!$A:$A,"Bahamians",'Keyword Results'!$M:$M) -> 0 | L12: =SUMIF('Keyword Results'!$A:$A,"Bahamians",'Keyword Results'!$N:$N) -> 0 | M12: =SUMIF('Keyword Results'!$A:$A,"Bahamians",'Keyword Results'!$O:$O) -> 0 | N12: =SUMIF('Keyword Results'!$A:$A,"Bahamians",'Keyword Results'!$P:$P) -> 0 | O12: =SUMIF('Keyword Results'!$A:$A,"Bahamians",'Keyword Results'!$Q:$Q) -> 0 | P12: =SUMIF('Keyword Results'!$A:$A,"Bahamians",'Keyword Results'!$R:$R) -> 0 | Q12: =SUMIF('Keyword Results'!$A:$A,"Bahamians",'Keyword Results'!$S:$S) -> 0 | R12: =SUMIF('Keyword Results'!$A:$A,"Bahamians",'Keyword Results'!$T:$T) -> 0 | S12: =SUMIF('Keyword Results'!$A:$A,"Bahamians",'Keyword Results'!$U:$U) -> 0 | T12: =SUMIF('Keyword Results'!$A:$A,"Bahamians",'Keyword Results'!$V:$V) -> 0 | U12: =SUMIF('Keyword Results'!$A:$A,"Bahamians",'Keyword Results'!$W:$W) -> 0 | V12: =SUMIF('Keyword Results'!$A:$A,"Bahamians",'Keyword Results'!$X:$X) -> 0 | W12: =SUM(C12:V12) -> 0
A13: Bangladeshis | B13: =SUMIF('Keyword Results'!$A:$A,"Bangladeshis",'Keyword Results'!$D:$D) -> 8 | C13: =SUMIF('Keyword Results'!$A:$A,"Bangladeshis",'Keyword Results'!$E:$E) -> 1 | D13: =SUMIF('Keyword Results'!$A:$A,"Bangladeshis",'Keyword Results'!$F:$F) -> 0 | E13: =SUMIF('Keyword Results'!$A:$A,"Bangladeshis",'Keyword Results'!$G:$G) -> 0 | F13: =SUMIF('Keyword Results'!$A:$A,"Bangladeshis",'Keyword Results'!$H:$H) -> 0 | G13: =SUMIF('Keyword Results'!$A:$A,"Bangladeshis",'Keyword Results'!$I:$I) -> 0 | H13: =SUMIF('Keyword Results'!$A:$A,"Bangladeshis",'Keyword Results'!$J:$J) -> 0 | I13: =SUMIF('Keyword Results'!$A:$A,"Bangladeshis",'Keyword Results'!$K:$K) -> 0 | J13: =SUMIF('Keyword Results'!$A:$A,"Bangladeshis",'Keyword Results'!$L:$L) -> 0 | K13: =SUMIF('Keyword Results'!$A:$A,"Bangladeshis",'Keyword Results'!$M:$M) -> 0 | L13: =SUMIF('Keyword Results'!$A:$A,"Bangladeshis",'Keyword Results'!$N:$N) -> 0 | M13: =SUMIF('Keyword Results'!$A:$A,"Bangladeshis",'Keyword Results'!$O:$O) -> 0 | N13: =SUMIF('Keyword Results'!$A:$A,"Bangladeshis",'Keyword Results'!$P:$P) -> 0 | O13: =SUMIF('Keyword Results'!$A:$A,"Bangladeshis",'Keyword Results'!$Q:$Q) -> 0 | P13: =SUMIF('Keyword Results'!$A:$A,"Bangladeshis",'Keyword Results'!$R:$R) -> 0 | Q13: =SUMIF('Keyword Results'!$A:$A,"Bangladeshis",'Keyword Results'!$S:$S) -> 0 | R13: =SUMIF('Keyword Results'!$A:$A,"Bangladeshis",'Keyword Results'!$T:$T) -> 0 | S13: =SUMIF('Keyword Results'!$A:$A,"Bangladeshis",'Keyword Results'!$U:$U) -> 0 | T13: =SUMIF('Keyword Results'!$A:$A,"Bangladeshis",'Keyword Results'!$V:$V) -> 0 | U13: =SUMIF('Keyword Results'!$A:$A,"Bangladeshis",'Keyword Results'!$W:$W) -> 0 | V13: =SUMIF('Keyword Results'!$A:$A,"Bangladeshis",'Keyword Results'!$X:$X) -> 0 | W13: =SUM(C13:V13) -> 1
A14: Barbadians | B14: =SUMIF('Keyword Results'!$A:$A,"Barbadians",'Keyword Results'!$D:$D) -> 7 | C14: =SUMIF('Keyword Results'!$A:$A,"Barbadians",'Keyword Results'!$E:$E) -> 0 | D14: =SUMIF('Keyword Results'!$A:$A,"Barbadians",'Keyword Results'!$F:$F) -> 0 | E14: =SUMIF('Keyword Results'!$A:$A,"Barbadians",'Keyword Results'!$G:$G) -> 0 | F14: =SUMIF('Keyword Results'!$A:$A,"Barbadians",'Keyword Results'!$H:$H) -> 0 | G14: =SUMIF('Keyword Results'!$A:$A,"Barbadians",'Keyword Results'!$I:$I) -> 0 | H14: =SUMIF('Keyword Results'!$A:$A,"Barbadians",'Keyword Results'!$J:$J) -> 0 | I14: =SUMIF('Keyword Results'!$A:$A,"Barbadians",'Keyword Results'!$K:$K) -> 0 | J14: =SUMIF('Keyword Results'!$A:$A,"Barbadians",'Keyword Results'!$L:$L) -> 0 | K14: =SUMIF('Keyword Results'!$A:$A,"Barbadians",'Keyword Results'!$M:$M) -> 0 | L14: =SUMIF('Keyword Results'!$A:$A,"Barbadians",'Keyword Results'!$N:$N) -> 0 | M14: =SUMIF('Keyword Results'!$A:$A,"Barbadians",'Keyword Results'!$O:$O) -> 0 | N14: =SUMIF('Keyword Results'!$A:$A,"Barbadians",'Keyword Results'!$P:$P) -> 0 | O14: =SUMIF('Keyword Results'!$A:$A,"Barbadians",'Keyword Results'!$Q:$Q) -> 0 | P14: =SUMIF('Keyword Results'!$A:$A,"Barbadians",'Keyword Results'!$R:$R) -> 0 | Q14: =SUMIF('Keyword Results'!$A:$A,"Barbadians",'Keyword Results'!$S:$S) -> 0 | R14: =SUMIF('Keyword Results'!$A:$A,"Barbadians",'Keyword Results'!$T:$T) -> 0 | S14: =SUMIF('Keyword Results'!$A:$A,"Barbadians",'Keyword Results'!$U:$U) -> 0 | T14: =SUMIF('Keyword Results'!$A:$A,"Barbadians",'Keyword Results'!$V:$V) -> 0 | U14: =SUMIF('Keyword Results'!$A:$A,"Barbadians",'Keyword Results'!$W:$W) -> 0 | V14: =SUMIF('Keyword Results'!$A:$A,"Barbadians",'Keyword Results'!$X:$X) -> 0 | W14: =SUM(C14:V14) -> 0
A15: Belarusians | B15: =SUMIF('Keyword Results'!$A:$A,"Belarusians",'Keyword Results'!$D:$D) -> 8 | C15: =SUMIF('Keyword Results'!$A:$A,"Belarusians",'Keyword Results'!$E:$E) -> 0 | D15: =SUMIF('Keyword Results'!$A:$A,"Belarusians",'Keyword Results'!$F:$F) -> 0 | E15: =SUMIF('Keyword Results'!$A:$A,"Belarusians",'Keyword Results'!$G:$G) -> 0 | F15: =SUMIF('Keyword Results'!$A:$A,"Belarusians",'Keyword Results'!$H:$H) -> 0 | G15: =SUMIF('Keyword Results'!$A:$A,"Belarusians",'Keyword Results'!$I:$I) -> 0 | H15: =SUMIF('Keyword Results'!$A:$A,"Belarusians",'Keyword Results'!$J:$J) -> 0 | I15: =SUMIF('Keyword Results'!$A:$A,"Belarusians",'Keyword Results'!$K:$K) -> 0 | J15: =SUMIF('Keyword Results'!$A:$A,"Belarusians",'Keyword Results'!$L:$L) -> 0 | K15: =SUMIF('Keyword Results'!$A:$A,"Belarusians",'Keyword Results'!$M:$M) -> 0 | L15: =SUMIF('Keyword Results'!$A:$A,"Belarusians",'Keyword Results'!$N:$N) -> 0 | M15: =SUMIF('Keyword Results'!$A:$A,"Belarusians",'Keyword Results'!$O:$O) -> 0 | N15: =SUMIF('Keyword Results'!$A:$A,"Belarusians",'Keyword Results'!$P:$P) -> 0 | O15: =SUMIF('Keyword Results'!$A:$A,"Belarusians",'Keyword Results'!$Q:$Q) -> 0 | P15: =SUMIF('Keyword Results'!$A:$A,"Belarusians",'Keyword Results'!$R:$R) -> 0 | Q15: =SUMIF('Keyword Results'!$A:$A,"Belarusians",'Keyword Results'!$S:$S) -> 0 | R15: =SUMIF('Keyword Results'!$A:$A,"Belarusians",'Keyword Results'!$T:$T) -> 0 | S15: =SUMIF('Keyword Results'!$A:$A,"Belarusians",'Keyword Results'!$U:$U) -> 0 | T15: =SUMIF('Keyword Results'!$A:$A,"Belarusians",'Keyword Results'!$V:$V) -> 0 | U15: =SUMIF('Keyword Results'!$A:$A,"Belarusians",'Keyword Results'!$W:$W) -> 0 | V15: =SUMIF('Keyword Results'!$A:$A,"Belarusians",'Keyword Results'!$X:$X) -> 0 | W15: =SUM(C15:V15) -> 0
A16: Belgians | B16: =SUMIF('Keyword Results'!$A:$A,"Belgians",'Keyword Results'!$D:$D) -> 6 | C16: =SUMIF('Keyword Results'!$A:$A,"Belgians",'Keyword Results'!$E:$E) -> 0 | D16: =SUMIF('Keyword Results'!$A:$A,"Belgians",'Keyword Results'!$F:$F) -> 0 | E16: =SUMIF('Keyword Results'!$A:$A,"Belgians",'Keyword Results'!$G:$G) -> 0 | F16: =SUMIF('Keyword Results'!$A:$A,"Belgians",'Keyword Results'!$H:$H) -> 0 | G16: =SUMIF('Keyword Results'!$A:$A,"Belgians",'Keyword Results'!$I:$I) -> 0 | H16: =SUMIF('Keyword Results'!$A:$A,"Belgians",'Keyword Results'!$J:$J) -> 0 | I16: =SUMIF('Keyword Results'!$A:$A,"Belgians",'Keyword Results'!$K:$K) -> 0 | J16: =SUMIF('Keyword Results'!$A:$A,"Belgians",'Keyword Results'!$L:$L) -> 0 | K16: =SUMIF('Keyword Results'!$A:$A,"Belgians",'Keyword Results'!$M:$M) -> 0 | L16: =SUMIF('Keyword Results'!$A:$A,"Belgians",'Keyword Results'!$N:$N) -> 0 | M16: =SUMIF('Keyword Results'!$A:$A,"Belgians",'Keyword Results'!$O:$O) -> 0 | N16: =SUMIF('Keyword Results'!$A:$A,"Belgians",'Keyword Results'!$P:$P) -> 0 | O16: =SUMIF('Keyword Results'!$A:$A,"Belgians",'Keyword Results'!$Q:$Q) -> 0 | P16: =SUMIF('Keyword Results'!$A:$A,"Belgians",'Keyword Results'!$R:$R) -> 0 | Q16: =SUMIF('Keyword Results'!$A:$A,"Belgians",'Keyword Results'!$S:$S) -> 0 | R16: =SUMIF('Keyword Results'!$A:$A,"Belgians",'Keyword Results'!$T:$T) -> 0 | S16: =SUMIF('Keyword Results'!$A:$A,"Belgians",'Keyword Results'!$U:$U) -> 0 | T16: =SUMIF('Keyword Results'!$A:$A,"Belgians",'Keyword Results'!$V:$V) -> 0 | U16: =SUMIF('Keyword Results'!$A:$A,"Belgians",'Keyword Results'!$W:$W) -> 0 | V16: =SUMIF('Keyword Results'!$A:$A,"Belgians",'Keyword Results'!$X:$X) -> 0 | W16: =SUM(C16:V16) -> 0
A17: Belizeans | B17: =SUMIF('Keyword Results'!$A:$A,"Belizeans",'Keyword Results'!$D:$D) -> 6 | C17: =SUMIF('Keyword Results'!$A:$A,"Belizeans",'Keyword Results'!$E:$E) -> 0 | D17: =SUMIF('Keyword Results'!$A:$A,"Belizeans",'Keyword Results'!$F:$F) -> 0 | E17: =SUMIF('Keyword Results'!$A:$A,"Belizeans",'Keyword Results'!$G:$G) -> 0 | F17: =SUMIF('Keyword Results'!$A:$A,"Belizeans",'Keyword Results'!$H:$H) -> 0 | G17: =SUMIF('Keyword Results'!$A:$A,"Belizeans",'Keyword Results'!$I:$I) -> 0 | H17: =SUMIF('Keyword Results'!$A:$A,"Belizeans",'Keyword Results'!$J:$J) -> 0 | I17: =SUMIF('Keyword Results'!$A:$A,"Belizeans",'Keyword Results'!$K:$K) -> 0 | J17: =SUMIF('Keyword Results'!$A:$A,"Belizeans",'Keyword Results'!$L:$L) -> 0 | K17: =SUMIF('Keyword Results'!$A:$A,"Belizeans",'Keyword Results'!$M:$M) -> 0 | L17: =SUMIF('Keyword Results'!$A:$A,"Belizeans",'Keyword Results'!$N:$N) -> 0 | M17: =SUMIF('Keyword Results'!$A:$A,"Belizeans",'Keyword Results'!$O:$O) -> 0 | N17: =SUMIF('Keyword Results'!$A:$A,"Belizeans",'Keyword Results'!$P:$P) -> 0 | O17: =SUMIF('Keyword Results'!$A:$A,"Belizeans",'Keyword Results'!$Q:$Q) -> 0 | P17: =SUMIF('Keyword Results'!$A:$A,"Belizeans",'Keyword Results'!$R:$R) -> 0 | Q17: =SUMIF('Keyword Results'!$A:$A,"Belizeans",'Keyword Results'!$S:$S) -> 0 | R17: =SUMIF('Keyword Results'!$A:$A,"Belizeans",'Keyword Results'!$T:$T) -> 0 | S17: =SUMIF('Keyword Results'!$A:$A,"Belizeans",'Keyword Results'!$U:$U) -> 0 | T17: =SUMIF('Keyword Results'!$A:$A,"Belizeans",'Keyword Results'!$V:$V) -> 0 | U17: =SUMIF('Keyword Results'!$A:$A,"Belizeans",'Keyword Results'!$W:$W) -> 0 | V17: =SUMIF('Keyword Results'!$A:$A,"Belizeans",'Keyword Results'!$X:$X) -> 0 | W17: =SUM(C17:V17) -> 0
A18: Bolivians | B18: =SUMIF('Keyword Results'!$A:$A,"Bolivians",'Keyword Results'!$D:$D) -> 9 | C18: =SUMIF('Keyword Results'!$A:$A,"Bolivians",'Keyword Results'!$E:$E) -> 0 | D18: =SUMIF('Keyword Results'!$A:$A,"Bolivians",'Keyword Results'!$F:$F) -> 0 | E18: =SUMIF('Keyword Results'!$A:$A,"Bolivians",'Keyword Results'!$G:$G) -> 0 | F18: =SUMIF('Keyword Results'!$A:$A,"Bolivians",'Keyword Results'!$H:$H) -> 0 | G18: =SUMIF('Keyword Results'!$A:$A,"Bolivians",'Keyword Results'!$I:$I) -> 0 | H18: =SUMIF('Keyword Results'!$A:$A,"Bolivians",'Keyword Results'!$J:$J) -> 0 | I18: =SUMIF('Keyword Results'!$A:$A,"Bolivians",'Keyword Results'!$K:$K) -> 0 | J18: =SUMIF('Keyword Results'!$A:$A,"Bolivians",'Keyword Results'!$L:$L) -> 0 | K18: =SUMIF('Keyword Results'!$A:$A,"Bolivians",'Keyword Results'!$M:$M) -> 0 | L18: =SUMIF('Keyword Results'!$A:$A,"Bolivians",'Keyword Results'!$N:$N) -> 0 | M18: =SUMIF('Keyword Results'!$A:$A,"Bolivians",'Keyword Results'!$O:$O) -> 0 | N18: =SUMIF('Keyword Results'!$A:$A,"Bolivians",'Keyword Results'!$P:$P) -> 0 | O18: =SUMIF('Keyword Results'!$A:$A,"Bolivians",'Keyword Results'!$Q:$Q) -> 0 | P18: =SUMIF('Keyword Results'!$A:$A,"Bolivians",'Keyword Results'!$R:$R) -> 0 | Q18: =SUMIF('Keyword Results'!$A:$A,"Bolivians",'Keyword Results'!$S:$S) -> 0 | R18: =SUMIF('Keyword Results'!$A:$A,"Bolivians",'Keyword Results'!$T:$T) -> 0 | S18: =SUMIF('Keyword Results'!$A:$A,"Bolivians",'Keyword Results'!$U:$U) -> 0 | T18: =SUMIF('Keyword Results'!$A:$A,"Bolivians",'Keyword Results'!$V:$V) -> 0 | U18: =SUMIF('Keyword Results'!$A:$A,"Bolivians",'Keyword Results'!$W:$W) -> 0 | V18: =SUMIF('Keyword Results'!$A:$A,"Bolivians",'Keyword Results'!$X:$X) -> 0 | W18: =SUM(C18:V18) -> 0
A19: Brazilians | B19: =SUMIF('Keyword Results'!$A:$A,"Brazilians",'Keyword Results'!$D:$D) -> 14 | C19: =SUMIF('Keyword Results'!$A:$A,"Brazilians",'Keyword Results'!$E:$E) -> 1 | D19: =SUMIF('Keyword Results'!$A:$A,"Brazilians",'Keyword Results'!$F:$F) -> 0 | E19: =SUMIF('Keyword Results'!$A:$A,"Brazilians",'Keyword Results'!$G:$G) -> 0 | F19: =SUMIF('Keyword Results'!$A:$A,"Brazilians",'Keyword Results'!$H:$H) -> 0 | G19: =SUMIF('Keyword Results'!$A:$A,"Brazilians",'Keyword Results'!$I:$I) -> 0 | H19: =SUMIF('Keyword Results'!$A:$A,"Brazilians",'Keyword Results'!$J:$J) -> 0 | I19: =SUMIF('Keyword Results'!$A:$A,"Brazilians",'Keyword Results'!$K:$K) -> 0 | J19: =SUMIF('Keyword Results'!$A:$A,"Brazilians",'Keyword Results'!$L:$L) -> 0 | K19: =SUMIF('Keyword Results'!$A:$A,"Brazilians",'Keyword Results'!$M:$M) -> 0 | L19: =SUMIF('Keyword Results'!$A:$A,"Brazilians",'Keyword Results'!$N:$N) -> 0 | M19: =SUMIF('Keyword Results'!$A:$A,"Brazilians",'Keyword Results'!$O:$O) -> 0 | N19: =SUMIF('Keyword Results'!$A:$A,"Brazilians",'Keyword Results'!$P:$P) -> 0 | O19: =SUMIF('Keyword Results'!$A:$A,"Brazilians",'Keyword Results'!$Q:$Q) -> 0 | P19: =SUMIF('Keyword Results'!$A:$A,"Brazilians",'Keyword Results'!$R:$R) -> 0 | Q19: =SUMIF('Keyword Results'!$A:$A,"Brazilians",'Keyword Results'!$S:$S) -> 0 | R19: =SUMIF('Keyword Results'!$A:$A,"Brazilians",'Keyword Results'!$T:$T) -> 0 | S19: =SUMIF('Keyword Results'!$A:$A,"Brazilians",'Keyword Results'!$U:$U) -> 0 | T19: =SUMIF('Keyword Results'!$A:$A,"Brazilians",'Keyword Results'!$V:$V) -> 0 | U19: =SUMIF('Keyword Results'!$A:$A,"Brazilians",'Keyword Results'!$W:$W) -> 0 | V19: =SUMIF('Keyword Results'!$A:$A,"Brazilians",'Keyword Results'!$X:$X) -> 0 | W19: =SUM(C19:V19) -> 1
A20: British_people | B20: =SUMIF('Keyword Results'!$A:$A,"British_people",'Keyword Results'!$D:$D) -> 14 | C20: =SUMIF('Keyword Results'!$A:$A,"British_people",'Keyword Results'!$E:$E) -> 9 | D20: =SUMIF('Keyword Results'!$A:$A,"British_people",'Keyword Results'!$F:$F) -> 1 | E20: =SUMIF('Keyword Results'!$A:$A,"British_people",'Keyword Results'!$G:$G) -> 0 | F20: =SUMIF('Keyword Results'!$A:$A,"British_people",'Keyword Results'!$H:$H) -> 0 | G20: =SUMIF('Keyword Results'!$A:$A,"British_people",'Keyword Results'!$I:$I) -> 0 | H20: =SUMIF('Keyword Results'!$A:$A,"British_people",'Keyword Results'!$J:$J) -> 0 | I20: =SUMIF('Keyword Results'!$A:$A,"British_people",'Keyword Results'!$K:$K) -> 0 | J20: =SUMIF('Keyword Results'!$A:$A,"British_people",'Keyword Results'!$L:$L) -> 0 | K20: =SUMIF('Keyword Results'!$A:$A,"British_people",'Keyword Results'!$M:$M) -> 0 | L20: =SUMIF('Keyword Results'!$A:$A,"British_people",'Keyword Results'!$N:$N) -> 0 | M20: =SUMIF('Keyword Results'!$A:$A,"British_people",'Keyword Results'!$O:$O) -> 0 | N20: =SUMIF('Keyword Results'!$A:$A,"British_people",'Keyword Results'!$P:$P) -> 0 | O20: =SUMIF('Keyword Results'!$A:$A,"British_people",'Keyword Results'!$Q:$Q) -> 0 | P20: =SUMIF('Keyword Results'!$A:$A,"British_people",'Keyword Results'!$R:$R) -> 0 | Q20: =SUMIF('Keyword Results'!$A:$A,"British_people",'Keyword Results'!$S:$S) -> 0 | R20: =SUMIF('Keyword Results'!$A:$A,"British_people",'Keyword Results'!$T:$T) -> 0 | S20: =SUMIF('Keyword Results'!$A:$A,"British_people",'Keyword Results'!$U:$U) -> 0 | T20: =SUMIF('Keyword Results'!$A:$A,"British_people",'Keyword Results'!$V:$V) -> 0 | U20: =SUMIF('Keyword Results'!$A:$A,"British_people",'Keyword Results'!$W:$W) -> 0 | V20: =SUMIF('Keyword Results'!$A:$A,"British_people",'Keyword Results'!$X:$X) -> 0 | W20: =SUM(C20:V20) -> 10
A21: Bulgarians | B21: =SUMIF('Keyword Results'!$A:$A,"Bulgarians",'Keyword Results'!$D:$D) -> 6 | C21: =SUMIF('Keyword Results'!$A:$A,"Bulgarians",'Keyword Results'!$E:$E) -> 1 | D21: =SUMIF('Keyword Results'!$A:$A,"Bulgarians",'Keyword Results'!$F:$F) -> 0 | E21: =SUMIF('Keyword Results'!$A:$A,"Bulgarians",'Keyword Results'!$G:$G) -> 0 | F21: =SUMIF('Keyword Results'!$A:$A,"Bulgarians",'Keyword Results'!$H:$H) -> 0 | G21: =SUMIF('Keyword Results'!$A:$A,"Bulgarians",'Keyword Results'!$I:$I) -> 0 | H21: =SUMIF('Keyword Results'!$A:$A,"Bulgarians",'Keyword Results'!$J:$J) -> 0 | I21: =SUMIF('Keyword Results'!$A:$A,"Bulgarians",'Keyword Results'!$K:$K) -> 0 | J21: =SUMIF('Keyword Results'!$A:$A,"Bulgarians",'Keyword Results'!$L:$L) -> 0 | K21: =SUMIF('Keyword Results'!$A:$A,"Bulgarians",'Keyword Results'!$M:$M) -> 0 | L21: =SUMIF('Keyword Results'!$A:$A,"Bulgarians",'Keyword Results'!$N:$N) -> 0 | M21: =SUMIF('Keyword Results'!$A:$A,"Bulgarians",'Keyword Results'!$O:$O) -> 0 | N21: =SUMIF('Keyword Results'!$A:$A,"Bulgarians",'Keyword Results'!$P:$P) -> 0 | O21: =SUMIF('Keyword Results'!$A:$A,"Bulgarians",'Keyword Results'!$Q:$Q) -> 0 | P21: =SUMIF('Keyword Results'!$A:$A,"Bulgarians",'Keyword Results'!$R:$R) -> 0 | Q21: =SUMIF('Keyword Results'!$A:$A,"Bulgarians",'Keyword Results'!$S:$S) -> 0 | R21: =SUMIF('Keyword Results'!$A:$A,"Bulgarians",'Keyword Results'!$T:$T) -> 0 | S21: =SUMIF('Keyword Results'!$A:$A,"Bulgarians",'Keyword Results'!$U:$U) -> 0 | T21: =SUMIF('Keyword Results'!$A:$A,"Bulgarians",'Keyword Results'!$V:$V) -> 0 | U21: =SUMIF('Keyword Results'!$A:$A,"Bulgarians",'Keyword Results'!$W:$W) -> 0 | V21: =SUMIF('Keyword Results'!$A:$A,"Bulgarians",'Keyword Results'!$X:$X) -> 0 | W21: =SUM(C21:V21) -> 1
A22: Burmese_people | B22: =SUMIF('Keyword Results'!$A:$A,"Burmese_people",'Keyword Results'!$D:$D) -> 10 | C22: =SUMIF('Keyword Results'!$A:$A,"Burmese_people",'Keyword Results'!$E:$E) -> 2 | D22: =SUMIF('Keyword Results'!$A:$A,"Burmese_people",'Keyword Results'!$F:$F) -> 0 | E22: =SUMIF('Keyword Results'!$A:$A,"Burmese_people",'Keyword Results'!$G:$G) -> 0 | F22: =SUMIF('Keyword Results'!$A:$A,"Burmese_people",'Keyword Results'!$H:$H) -> 0 | G22: =SUMIF('Keyword Results'!$A:$A,"Burmese_people",'Keyword Results'!$I:$I) -> 0 | H22: =SUMIF('Keyword Results'!$A:$A,"Burmese_people",'Keyword Results'!$J:$J) -> 0 | I22: =SUMIF('Keyword Results'!$A:$A,"Burmese_people",'Keyword Results'!$K:$K) -> 0 | J22: =SUMIF('Keyword Results'!$A:$A,"Burmese_people",'Keyword Results'!$L:$L) -> 0 | K22: =SUMIF('Keyword Results'!$A:$A,"Burmese_people",'Keyword Results'!$M:$M) -> 0 | L22: =SUMIF('Keyword Results'!$A:$A,"Burmese_people",'Keyword Results'!$N:$N) -> 0 | M22: =SUMIF('Keyword Results'!$A:$A,"Burmese_people",'Keyword Results'!$O:$O) -> 0 | N22: =SUMIF('Keyword Results'!$A:$A,"Burmese_people",'Keyword Results'!$P:$P) -> 0 | O22: =SUMIF('Keyword Results'!$A:$A,"Burmese_people",'Keyword Results'!$Q:$Q) -> 0 | P22: =SUMIF('Keyword Results'!$A:$A,"Burmese_people",'Keyword Results'!$R:$R) -> 0 | Q22: =SUMIF('Keyword Results'!$A:$A,"Burmese_people",'Keyword Results'!$S:$S) -> 0 | R22: =SUMIF('Keyword Results'!$A:$A,"Burmese_people",'Keyword Results'!$T:$T) -> 0 | S22: =SUMIF('Keyword Results'!$A:$A,"Burmese_people",'Keyword Results'!$U:$U) -> 0 | T22: =SUMIF('Keyword Results'!$A:$A,"Burmese_people",'Keyword Results'!$V:$V) -> 0 | U22: =SUMIF('Keyword Results'!$A:$A,"Burmese_people",'Keyword Results'!$W:$W) -> 0 | V22: =SUMIF('Keyword Results'!$A:$A,"Burmese_people",'Keyword Results'!$X:$X) -> 0 | W22: =SUM(C22:V22) -> 2
A23: Canadians | B23: =SUMIF('Keyword Results'!$A:$A,"Canadians",'Keyword Results'!$D:$D) -> 5 | C23: =SUMIF('Keyword Results'!$A:$A,"Canadians",'Keyword Results'!$E:$E) -> 0 | D23: =SUMIF('Keyword Results'!$A:$A,"Canadians",'Keyword Results'!$F:$F) -> 0 | E23: =SUMIF('Keyword Results'!$A:$A,"Canadians",'Keyword Results'!$G:$G) -> 0 | F23: =SUMIF('Keyword Results'!$A:$A,"Canadians",'Keyword Results'!$H:$H) -> 0 | G23: =SUMIF('Keyword Results'!$A:$A,"Canadians",'Keyword Results'!$I:$I) -> 0 | H23: =SUMIF('Keyword Results'!$A:$A,"Canadians",'Keyword Results'!$J:$J) -> 0 | I23: =SUMIF('Keyword Results'!$A:$A,"Canadians",'Keyword Results'!$K:$K) -> 0 | J23: =SUMIF('Keyword Results'!$A:$A,"Canadians",'Keyword Results'!$L:$L) -> 0 | K23: =SUMIF('Keyword Results'!$A:$A,"Canadians",'Keyword Results'!$M:$M) -> 0 | L23: =SUMIF('Keyword Results'!$A:$A,"Canadians",'Keyword Results'!$N:$N) -> 0 | M23: =SUMIF('Keyword Results'!$A:$A,"Canadians",'Keyword Results'!$O:$O) -> 0 | N23: =SUMIF('Keyword Results'!$A:$A,"Canadians",'Keyword Results'!$P:$P) -> 0 | O23: =SUMIF('Keyword Results'!$A:$A,"Canadians",'Keyword Results'!$Q:$Q) -> 0 | P23: =SUMIF('Keyword Results'!$A:$A,"Canadians",'Keyword Results'!$R:$R) -> 0 | Q23: =SUMIF('Keyword Results'!$A:$A,"Canadians",'Keyword Results'!$S:$S) -> 0 | R23: =SUMIF('Keyword Results'!$A:$A,"Canadians",'Keyword Results'!$T:$T) -> 0 | S23: =SUMIF('Keyword Results'!$A:$A,"Canadians",'Keyword Results'!$U:$U) -> 0 | T23: =SUMIF('Keyword Results'!$A:$A,"Canadians",'Keyword Results'!$V:$V) -> 0 | U23: =SUMIF('Keyword Results'!$A:$A,"Canadians",'Keyword Results'!$W:$W) -> 0 | V23: =SUMIF('Keyword Results'!$A:$A,"Canadians",'Keyword Results'!$X:$X) -> 0 | W23: =SUM(C23:V23) -> 0
A24: Cape_Verdeans | B24: =SUMIF('Keyword Results'!$A:$A,"Cape_Verdeans",'Keyword Results'!$D:$D) -> 7 | C24: =SUMIF('Keyword Results'!$A:$A,"Cape_Verdeans",'Keyword Results'!$E:$E) -> 0 | D24: =SUMIF('Keyword Results'!$A:$A,"Cape_Verdeans",'Keyword Results'!$F:$F) -> 0 | E24: =SUMIF('Keyword Results'!$A:$A,"Cape_Verdeans",'Keyword Results'!$G:$G) -> 0 | F24: =SUMIF('Keyword Results'!$A:$A,"Cape_Verdeans",'Keyword Results'!$H:$H) -> 0 | G24: =SUMIF('Keyword Results'!$A:$A,"Cape_Verdeans",'Keyword Results'!$I:$I) -> 0 | H24: =SUMIF('Keyword Results'!$A:$A,"Cape_Verdeans",'Keyword Results'!$J:$J) -> 0 | I24: =SUMIF('Keyword Results'!$A:$A,"Cape_Verdeans",'Keyword Results'!$K:$K) -> 0 | J24: =SUMIF('Keyword Results'!$A:$A,"Cape_Verdeans",'Keyword Results'!$L:$L) -> 0 | K24: =SUMIF('Keyword Results'!$A:$A,"Cape_Verdeans",'Keyword Results'!$M:$M) -> 0 | L24: =SUMIF('Keyword Results'!$A:$A,"Cape_Verdeans",'Keyword Results'!$N:$N) -> 0 | M24: =SUMIF('Keyword Results'!$A:$A,"Cape_Verdeans",'Keyword Results'!$O:$O) -> 0 | N24: =SUMIF('Keyword Results'!$A:$A,"Cape_Verdeans",'Keyword Results'!$P:$P) -> 0 | O24: =SUMIF('Keyword Results'!$A:$A,"Cape_Verdeans",'Keyword Results'!$Q:$Q) -> 0 | P24: =SUMIF('Keyword Results'!$A:$A,"Cape_Verdeans",'Keyword Results'!$R:$R) -> 0 | Q24: =SUMIF('Keyword Results'!$A:$A,"Cape_Verdeans",'Keyword Results'!$S:$S) -> 0 | R24: =SUMIF('Keyword Results'!$A:$A,"Cape_Verdeans",'Keyword Results'!$T:$T) -> 0 | S24: =SUMIF('Keyword Results'!$A:$A,"Cape_Verdeans",'Keyword Results'!$U:$U) -> 0 | T24: =SUMIF('Keyword Results'!$A:$A,"Cape_Verdeans",'Keyword Results'!$V:$V) -> 0 | U24: =SUMIF('Keyword Results'!$A:$A,"Cape_Verdeans",'Keyword Results'!$W:$W) -> 0 | V24: =SUMIF('Keyword Results'!$A:$A,"Cape_Verdeans",'Keyword Results'!$X:$X) -> 0 | W24: =SUM(C24:V24) -> 0
A25: Chileans | B25: =SUMIF('Keyword Results'!$A:$A,"Chileans",'Keyword Results'!$D:$D) -> 9 | C25: =SUMIF('Keyword Results'!$A:$A,"Chileans",'Keyword Results'!$E:$E) -> 0 | D25: =SUMIF('Keyword Results'!$A:$A,"Chileans",'Keyword Results'!$F:$F) -> 0 | E25: =SUMIF('Keyword Results'!$A:$A,"Chileans",'Keyword Results'!$G:$G) -> 0 | F25: =SUMIF('Keyword Results'!$A:$A,"Chileans",'Keyword Results'!$H:$H) -> 0 | G25: =SUMIF('Keyword Results'!$A:$A,"Chileans",'Keyword Results'!$I:$I) -> 0 | H25: =SUMIF('Keyword Results'!$A:$A,"Chileans",'Keyword Results'!$J:$J) -> 0 | I25: =SUMIF('Keyword Results'!$A:$A,"Chileans",'Keyword Results'!$K:$K) -> 0 | J25: =SUMIF('Keyword Results'!$A:$A,"Chileans",'Keyword Results'!$L:$L) -> 0 | K25: =SUMIF('Keyword Results'!$A:$A,"Chileans",'Keyword Results'!$M:$M) -> 0 | L25: =SUMIF('Keyword Results'!$A:$A,"Chileans",'Keyword Results'!$N:$N) -> 0 | M25: =SUMIF('Keyword Results'!$A:$A,"Chileans",'Keyword Results'!$O:$O) -> 0 | N25: =SUMIF('Keyword Results'!$A:$A,"Chileans",'Keyword Results'!$P:$P) -> 0 | O25: =SUMIF('Keyword Results'!$A:$A,"Chileans",'Keyword Results'!$Q:$Q) -> 0 | P25: =SUMIF('Keyword Results'!$A:$A,"Chileans",'Keyword Results'!$R:$R) -> 0 | Q25: =SUMIF('Keyword Results'!$A:$A,"Chileans",'Keyword Results'!$S:$S) -> 0 | R25: =SUMIF('Keyword Results'!$A:$A,"Chileans",'Keyword Results'!$T:$T) -> 0 | S25: =SUMIF('Keyword Results'!$A:$A,"Chileans",'Keyword Results'!$U:$U) -> 0 | T25: =SUMIF('Keyword Results'!$A:$A,"Chileans",'Keyword Results'!$V:$V) -> 0 | U25: =SUMIF('Keyword Results'!$A:$A,"Chileans",'Keyword Results'!$W:$W) -> 0 | V25: =SUMIF('Keyword Results'!$A:$A,"Chileans",'Keyword Results'!$X:$X) -> 0 | W25: =SUM(C25:V25) -> 0
A26: Chinese_people | B26: =SUMIF('Keyword Results'!$A:$A,"Chinese_people",'Keyword Results'!$D:$D) -> 5 | C26: =SUMIF('Keyword Results'!$A:$A,"Chinese_people",'Keyword Results'!$E:$E) -> 0 | D26: =SUMIF('Keyword Results'!$A:$A,"Chinese_people",'Keyword Results'!$F:$F) -> 0 | E26: =SUMIF('Keyword Results'!$A:$A,"Chinese_people",'Keyword Results'!$G:$G) -> 0 | F26: =SUMIF('Keyword Results'!$A:$A,"Chinese_people",'Keyword Results'!$H:$H) -> 0 | G26: =SUMIF('Keyword Results'!$A:$A,"Chinese_people",'Keyword Results'!$I:$I) -> 0 | H26: =SUMIF('Keyword Results'!$A:$A,"Chinese_people",'Keyword Results'!$J:$J) -> 0 | I26: =SUMIF('Keyword Results'!$A:$A,"Chinese_people",'Keyword Results'!$K:$K) -> 0 | J26: =SUMIF('Keyword Results'!$A:$A,"Chinese_people",'Keyword Results'!$L:$L) -> 0 | K26: =SUMIF('Keyword Results'!$A:$A,"Chinese_people",'Keyword Results'!$M:$M) -> 0 | L26: =SUMIF('Keyword Results'!$A:$A,"Chinese_people",'Keyword Results'!$N:$N) -> 0 | M26: =SUMIF('Keyword Results'!$A:$A,"Chinese_people",'Keyword Results'!$O:$O) -> 0 | N26: =SUMIF('Keyword Results'!$A:$A,"Chinese_people",'Keyword Results'!$P:$P) -> 0 | O26: =SUMIF('Keyword Results'!$A:$A,"Chinese_people",'Keyword Results'!$Q:$Q) -> 0 | P26: =SUMIF('Keyword Results'!$A:$A,"Chinese_people",'Keyword Results'!$R:$R) -> 0 | Q26: =SUMIF('Keyword Results'!$A:$A,"Chinese_people",'Keyword Results'!$S:$S) -> 0 | R26: =SUMIF('Keyword Results'!$A:$A,"Chinese_people",'Keyword Results'!$T:$T) -> 0 | S26: =SUMIF('Keyword Results'!$A:$A,"Chinese_people",'Keyword Results'!$U:$U) -> 0 | T26: =SUMIF('Keyword Results'!$A:$A,"Chinese_people",'Keyword Results'!$V:$V) -> 0 | U26: =SUMIF('Keyword Results'!$A:$A,"Chinese_people",'Keyword Results'!$W:$W) -> 0 | V26: =SUMIF('Keyword Results'!$A:$A,"Chinese_people",'Keyword Results'!$X:$X) -> 0 | W26: =SUM(C26:V26) -> 0
A27: Colombians | B27: =SUMIF('Keyword Results'!$A:$A,"Colombians",'Keyword Results'!$D:$D) -> 10 | C27: =SUMIF('Keyword Results'!$A:$A,"Colombians",'Keyword Results'!$E:$E) -> 0 | D27: =SUMIF('Keyword Results'!$A:$A,"Colombians",'Keyword Results'!$F:$F) -> 0 | E27: =SUMIF('Keyword Results'!$A:$A,"Colombians",'Keyword Results'!$G:$G) -> 3 | F27: =SUMIF('Keyword Results'!$A:$A,"Colombians",'Keyword Results'!$H:$H) -> 0 | G27: =SUMIF('Keyword Results'!$A:$A,"Colombians",'Keyword Results'!$I:$I) -> 0 | H27: =SUMIF('Keyword Results'!$A:$A,"Colombians",'Keyword Results'!$J:$J) -> 0 | I27: =SUMIF('Keyword Results'!$A:$A,"Colombians",'Keyword Results'!$K:$K) -> 0 | J27: =SUMIF('Keyword Results'!$A:$A,"Colombians",'Keyword Results'!$L:$L) -> 0 | K27: =SUMIF('Keyword Results'!$A:$A,"Colombians",'Keyword Results'!$M:$M) -> 0 | L27: =SUMIF('Keyword Results'!$A:$A,"Colombians",'Keyword Results'!$N:$N) -> 0 | M27: =SUMIF('Keyword Results'!$A:$A,"Colombians",'Keyword Results'!$O:$O) -> 0 | N27: =SUMIF('Keyword Results'!$A:$A,"Colombians",'Keyword Results'!$P:$P) -> 0 | O27: =SUMIF('Keyword Results'!$A:$A,"Colombians",'Keyword Results'!$Q:$Q) -> 0 | P27: =SUMIF('Keyword Results'!$A:$A,"Colombians",'Keyword Results'!$R:$R) -> 0 | Q27: =SUMIF('Keyword Results'!$A:$A,"Colombians",'Keyword Results'!$S:$S) -> 0 | R27: =SUMIF('Keyword Results'!$A:$A,"Colombians",'Keyword Results'!$T:$T) -> 0 | S27: =SUMIF('Keyword Results'!$A:$A,"Colombians",'Keyword Results'!$U:$U) -> 0 | T27: =SUMIF('Keyword Results'!$A:$A,"Colombians",'Keyword Results'!$V:$V) -> 0 | U27: =SUMIF('Keyword Results'!$A:$A,"Colombians",'Keyword Results'!$W:$W) -> 0 | V27: =SUMIF('Keyword Results'!$A:$A,"Colombians",'Keyword Results'!$X:$X) -> 0 | W27: =SUM(C27:V27) -> 3
A28: Cook_Islanders | B28: =SUMIF('Keyword Results'!$A:$A,"Cook_Islanders",'Keyword Results'!$D:$D) -> 9 | C28: =SUMIF('Keyword Results'!$A:$A,"Cook_Islanders",'Keyword Results'!$E:$E) -> 0 | D28: =SUMIF('Keyword Results'!$A:$A,"Cook_Islanders",'Keyword Results'!$F:$F) -> 0 | E28: =SUMIF('Keyword Results'!$A:$A,"Cook_Islanders",'Keyword Results'!$G:$G) -> 0 | F28: =SUMIF('Keyword Results'!$A:$A,"Cook_Islanders",'Keyword Results'!$H:$H) -> 0 | G28: =SUMIF('Keyword Results'!$A:$A,"Cook_Islanders",'Keyword Results'!$I:$I) -> 0 | H28: =SUMIF('Keyword Results'!$A:$A,"Cook_Islanders",'Keyword Results'!$J:$J) -> 0 | I28: =SUMIF('Keyword Results'!$A:$A,"Cook_Islanders",'Keyword Results'!$K:$K) -> 0 | J28: =SUMIF('Keyword Results'!$A:$A,"Cook_Islanders",'Keyword Results'!$L:$L) -> 0 | K28: =SUMIF('Keyword Results'!$A:$A,"Cook_Islanders",'Keyword Results'!$M:$M) -> 0 | L28: =SUMIF('Keyword Results'!$A:$A,"Cook_Islanders",'Keyword Results'!$N:$N) -> 0 | M28: =SUMIF('Keyword Results'!$A:$A,"Cook_Islanders",'Keyword Results'!$O:$O) -> 0 | N28: =SUMIF('Keyword Results'!$A:$A,"Cook_Islanders",'Keyword Results'!$P:$P) -> 0 | O28: =SUMIF('Keyword Results'!$A:$A,"Cook_Islanders",'Keyword Results'!$Q:$Q) -> 0 | P28: =SUMIF('Keyword Results'!$A:$A,"Cook_Islanders",'Keyword Results'!$R:$R) -> 0 | Q28: =SUMIF('Keyword Results'!$A:$A,"Cook_Islanders",'Keyword Results'!$S:$S) -> 0 | R28: =SUMIF('Keyword Results'!$A:$A,"Cook_Islanders",'Keyword Results'!$T:$T) -> 0 | S28: =SUMIF('Keyword Results'!$A:$A,"Cook_Islanders",'Keyword Results'!$U:$U) -> 0 | T28: =SUMIF('Keyword Results'!$A:$A,"Cook_Islanders",'Keyword Results'!$V:$V) -> 0 | U28: =SUMIF('Keyword Results'!$A:$A,"Cook_Islanders",'Keyword Results'!$W:$W) -> 0 | V28: =SUMIF('Keyword Results'!$A:$A,"Cook_Islanders",'Keyword Results'!$X:$X) -> 0 | W28: =SUM(C28:V28) -> 0
